Using backend: pytorch
Traceback (most recent call last):
  File "scripts/active/belief_active_plot.py", line 649, in <module>
    best_df, pro_ts_df, retro_ts_df = plot.generate()
  File "scripts/active/belief_active_plot.py", line 257, in generate
    final_results, prospective_beliefs, retrospective_beliefs = self.run_trials(ds)
  File "scripts/active/belief_active_plot.py", line 327, in run_trials
    acquisitions = self.bo.run(num_rounds=self.num_rounds)
  File "/home/nguyenm5/coding/pinot/pinot/active/experiment.py", line 388, in run
    self.train()
  File "/home/nguyenm5/coding/pinot/pinot/active/experiment.py", line 464, in train
    self.net = pinot.app.experiment.Train(
  File "/home/nguyenm5/coding/pinot/pinot/app/experiment.py", line 117, in train
    epoch_loss = self.train_once()
  File "/home/nguyenm5/coding/pinot/pinot/app/experiment.py", line 92, in train_once
    loss = torch.sum(self.net.loss(*x))
  File "/home/nguyenm5/coding/pinot/pinot/generative/semi_supervised_net.py", line 155, in loss
    total_loss = self.loss_unsupervised(g, h) * self.unsup_scale
  File "/home/nguyenm5/coding/pinot/pinot/generative/semi_supervised_net.py", line 267, in loss_unsupervised
    recon_loss = self.decoder.decode_and_compute_recon_error(g, z_sample)
  File "/home/nguyenm5/coding/pinot/pinot/generative/decoder.py", line 295, in decode_and_compute_recon_error
    decoded_subgraphs = self.forward(g, z_sample)
  File "/home/nguyenm5/coding/pinot/pinot/generative/decoder.py", line 412, in forward
    decoded_subgraphs = [
  File "/home/nguyenm5/coding/pinot/pinot/generative/decoder.py", line 413, in <listcomp>
    self.decode(g_sample.ndata["h"]) for g_sample in gs_unbatched
  File "/home/nguyenm5/coding/pinot/pinot/generative/decoder.py", line 373, in decode
    temp = torch.cat(
RuntimeError: CUDA out of memory. Tried to allocate 2.00 MiB (GPU 0; 7.80 GiB total capacity; 6.76 GiB already allocated; 3.12 MiB free; 6.78 GiB reserved in total by PyTorch)
Using backend: pytorch
Traceback (most recent call last):
  File "scripts/active/belief_active_plot.py", line 649, in <module>
    best_df, pro_ts_df, retro_ts_df = plot.generate()
  File "scripts/active/belief_active_plot.py", line 257, in generate
    final_results, prospective_beliefs, retrospective_beliefs = self.run_trials(ds)
  File "scripts/active/belief_active_plot.py", line 327, in run_trials
    acquisitions = self.bo.run(num_rounds=self.num_rounds)
  File "/home/nguyenm5/coding/pinot/pinot/active/experiment.py", line 388, in run
    self.train()
  File "/home/nguyenm5/coding/pinot/pinot/active/experiment.py", line 464, in train
    self.net = pinot.app.experiment.Train(
  File "/home/nguyenm5/coding/pinot/pinot/app/experiment.py", line 117, in train
    epoch_loss = self.train_once()
  File "/home/nguyenm5/coding/pinot/pinot/app/experiment.py", line 92, in train_once
    loss = torch.sum(self.net.loss(*x))
  File "/home/nguyenm5/coding/pinot/pinot/generative/semi_supervised_net.py", line 155, in loss
    total_loss = self.loss_unsupervised(g, h) * self.unsup_scale
  File "/home/nguyenm5/coding/pinot/pinot/generative/semi_supervised_net.py", line 267, in loss_unsupervised
    recon_loss = self.decoder.decode_and_compute_recon_error(g, z_sample)
  File "/home/nguyenm5/coding/pinot/pinot/generative/decoder.py", line 295, in decode_and_compute_recon_error
    decoded_subgraphs = self.forward(g, z_sample)
  File "/home/nguyenm5/coding/pinot/pinot/generative/decoder.py", line 412, in forward
    decoded_subgraphs = [
  File "/home/nguyenm5/coding/pinot/pinot/generative/decoder.py", line 413, in <listcomp>
    self.decode(g_sample.ndata["h"]) for g_sample in gs_unbatched
  File "/home/nguyenm5/coding/pinot/pinot/generative/decoder.py", line 382, in decode
    E_tilde = self.e_tensor_to_E_tilde(e_tensor.view(n * n, 2 * h))
  File "/home/nguyenm5/anaconda3/envs/pinot/lib/python3.8/site-packages/torch/nn/modules/module.py", line 550, in __call__
    result = self.forward(*input, **kwargs)
  File "/home/nguyenm5/anaconda3/envs/pinot/lib/python3.8/site-packages/torch/nn/modules/container.py", line 100, in forward
    input = module(input)
  File "/home/nguyenm5/anaconda3/envs/pinot/lib/python3.8/site-packages/torch/nn/modules/module.py", line 550, in __call__
    result = self.forward(*input, **kwargs)
  File "/home/nguyenm5/anaconda3/envs/pinot/lib/python3.8/site-packages/torch/nn/modules/activation.py", line 94, in forward
    return F.relu(input, inplace=self.inplace)
  File "/home/nguyenm5/anaconda3/envs/pinot/lib/python3.8/site-packages/torch/nn/functional.py", line 1063, in relu
    result = torch.relu(input)
RuntimeError: CUDA out of memory. Tried to allocate 2.00 MiB (GPU 0; 7.80 GiB total capacity; 6.76 GiB already allocated; 3.12 MiB free; 6.78 GiB reserved in total by PyTorch)
Using backend: pytorch
Traceback (most recent call last):
  File "scripts/active/belief_active_plot.py", line 649, in <module>
    best_df, pro_ts_df, retro_ts_df = plot.generate()
  File "scripts/active/belief_active_plot.py", line 257, in generate
    final_results, prospective_beliefs, retrospective_beliefs = self.run_trials(ds)
  File "scripts/active/belief_active_plot.py", line 327, in run_trials
    acquisitions = self.bo.run(num_rounds=self.num_rounds)
  File "/home/nguyenm5/coding/pinot/pinot/active/experiment.py", line 388, in run
    self.train()
  File "/home/nguyenm5/coding/pinot/pinot/active/experiment.py", line 464, in train
    self.net = pinot.app.experiment.Train(
  File "/home/nguyenm5/coding/pinot/pinot/app/experiment.py", line 117, in train
    epoch_loss = self.train_once()
  File "/home/nguyenm5/coding/pinot/pinot/app/experiment.py", line 92, in train_once
    loss = torch.sum(self.net.loss(*x))
  File "/home/nguyenm5/coding/pinot/pinot/generative/semi_supervised_net.py", line 155, in loss
    total_loss = self.loss_unsupervised(g, h) * self.unsup_scale
  File "/home/nguyenm5/coding/pinot/pinot/generative/semi_supervised_net.py", line 267, in loss_unsupervised
    recon_loss = self.decoder.decode_and_compute_recon_error(g, z_sample)
  File "/home/nguyenm5/coding/pinot/pinot/generative/decoder.py", line 295, in decode_and_compute_recon_error
    decoded_subgraphs = self.forward(g, z_sample)
  File "/home/nguyenm5/coding/pinot/pinot/generative/decoder.py", line 412, in forward
    decoded_subgraphs = [
  File "/home/nguyenm5/coding/pinot/pinot/generative/decoder.py", line 413, in <listcomp>
    self.decode(g_sample.ndata["h"]) for g_sample in gs_unbatched
  File "/home/nguyenm5/coding/pinot/pinot/generative/decoder.py", line 373, in decode
    temp = torch.cat(
RuntimeError: CUDA out of memory. Tried to allocate 2.00 MiB (GPU 0; 7.80 GiB total capacity; 6.76 GiB already allocated; 3.12 MiB free; 6.78 GiB reserved in total by PyTorch)
Using backend: pytorch
Traceback (most recent call last):
  File "scripts/active/belief_active_plot.py", line 649, in <module>
    best_df, pro_ts_df, retro_ts_df = plot.generate()
  File "scripts/active/belief_active_plot.py", line 257, in generate
    final_results, prospective_beliefs, retrospective_beliefs = self.run_trials(ds)
  File "scripts/active/belief_active_plot.py", line 327, in run_trials
    acquisitions = self.bo.run(num_rounds=self.num_rounds)
  File "/home/nguyenm5/coding/pinot/pinot/active/experiment.py", line 388, in run
    self.train()
  File "/home/nguyenm5/coding/pinot/pinot/active/experiment.py", line 464, in train
    self.net = pinot.app.experiment.Train(
  File "/home/nguyenm5/coding/pinot/pinot/app/experiment.py", line 117, in train
    epoch_loss = self.train_once()
  File "/home/nguyenm5/coding/pinot/pinot/app/experiment.py", line 92, in train_once
    loss = torch.sum(self.net.loss(*x))
  File "/home/nguyenm5/coding/pinot/pinot/generative/semi_supervised_net.py", line 153, in loss
    h = self.representation.forward(g, pool=None)  # We always call this
  File "/home/nguyenm5/coding/pinot/pinot/representation/sequential.py", line 344, in forward
    h = getattr(self, exe)(g, h)
  File "/home/nguyenm5/anaconda3/envs/pinot/lib/python3.8/site-packages/torch/nn/modules/module.py", line 550, in __call__
    result = self.forward(*input, **kwargs)
  File "/home/nguyenm5/anaconda3/envs/pinot/lib/python3.8/site-packages/dgl/nn/pytorch/conv/graphconv.py", line 156, in forward
    graph.update_all(fn.copy_src(src='h', out='m'),
  File "/home/nguyenm5/anaconda3/envs/pinot/lib/python3.8/site-packages/dgl/graph.py", line 3238, in update_all
    Runtime.run(prog)
  File "/home/nguyenm5/anaconda3/envs/pinot/lib/python3.8/site-packages/dgl/runtime/runtime.py", line 11, in run
    exe.run()
  File "/home/nguyenm5/anaconda3/envs/pinot/lib/python3.8/site-packages/dgl/runtime/ir/executor.py", line 1198, in run
    self.ret.data = F.copy_reduce(
  File "/home/nguyenm5/anaconda3/envs/pinot/lib/python3.8/site-packages/dgl/backend/pytorch/tensor.py", line 432, in copy_reduce
    out_data = in_data.new_empty((out_size,) + in_data.shape[1:])
RuntimeError: CUDA out of memory. Tried to allocate 350.00 MiB (GPU 0; 7.80 GiB total capacity; 6.23 GiB already allocated; 11.12 MiB free; 6.54 GiB reserved in total by PyTorch)
Using backend: pytorch
Traceback (most recent call last):
  File "scripts/active/belief_active_plot.py", line 649, in <module>
    best_df, pro_ts_df, retro_ts_df = plot.generate()
  File "scripts/active/belief_active_plot.py", line 257, in generate
    final_results, prospective_beliefs, retrospective_beliefs = self.run_trials(ds)
  File "scripts/active/belief_active_plot.py", line 327, in run_trials
    acquisitions = self.bo.run(num_rounds=self.num_rounds)
  File "/home/nguyenm5/coding/pinot/pinot/active/experiment.py", line 388, in run
    self.train()
  File "/home/nguyenm5/coding/pinot/pinot/active/experiment.py", line 464, in train
    self.net = pinot.app.experiment.Train(
  File "/home/nguyenm5/coding/pinot/pinot/app/experiment.py", line 117, in train
    epoch_loss = self.train_once()
  File "/home/nguyenm5/coding/pinot/pinot/app/experiment.py", line 92, in train_once
    loss = torch.sum(self.net.loss(*x))
  File "/home/nguyenm5/coding/pinot/pinot/generative/semi_supervised_net.py", line 153, in loss
    h = self.representation.forward(g, pool=None)  # We always call this
  File "/home/nguyenm5/coding/pinot/pinot/representation/sequential.py", line 344, in forward
    h = getattr(self, exe)(g, h)
  File "/home/nguyenm5/anaconda3/envs/pinot/lib/python3.8/site-packages/torch/nn/modules/module.py", line 550, in __call__
    result = self.forward(*input, **kwargs)
  File "/home/nguyenm5/anaconda3/envs/pinot/lib/python3.8/site-packages/dgl/nn/pytorch/conv/graphconv.py", line 156, in forward
    graph.update_all(fn.copy_src(src='h', out='m'),
  File "/home/nguyenm5/anaconda3/envs/pinot/lib/python3.8/site-packages/dgl/graph.py", line 3238, in update_all
    Runtime.run(prog)
  File "/home/nguyenm5/anaconda3/envs/pinot/lib/python3.8/site-packages/dgl/runtime/runtime.py", line 11, in run
    exe.run()
  File "/home/nguyenm5/anaconda3/envs/pinot/lib/python3.8/site-packages/dgl/runtime/ir/executor.py", line 1198, in run
    self.ret.data = F.copy_reduce(
  File "/home/nguyenm5/anaconda3/envs/pinot/lib/python3.8/site-packages/dgl/backend/pytorch/tensor.py", line 432, in copy_reduce
    out_data = in_data.new_empty((out_size,) + in_data.shape[1:])
RuntimeError: CUDA out of memory. Tried to allocate 350.00 MiB (GPU 0; 7.80 GiB total capacity; 6.23 GiB already allocated; 11.12 MiB free; 6.54 GiB reserved in total by PyTorch)
Using backend: pytorch
Traceback (most recent call last):
  File "scripts/active/belief_active_plot.py", line 649, in <module>
    best_df, pro_ts_df, retro_ts_df = plot.generate()
  File "scripts/active/belief_active_plot.py", line 257, in generate
    final_results, prospective_beliefs, retrospective_beliefs = self.run_trials(ds)
  File "scripts/active/belief_active_plot.py", line 327, in run_trials
    acquisitions = self.bo.run(num_rounds=self.num_rounds)
  File "/home/nguyenm5/coding/pinot/pinot/active/experiment.py", line 388, in run
    self.train()
  File "/home/nguyenm5/coding/pinot/pinot/active/experiment.py", line 464, in train
    self.net = pinot.app.experiment.Train(
  File "/home/nguyenm5/coding/pinot/pinot/app/experiment.py", line 117, in train
    epoch_loss = self.train_once()
  File "/home/nguyenm5/coding/pinot/pinot/app/experiment.py", line 92, in train_once
    loss = torch.sum(self.net.loss(*x))
  File "/home/nguyenm5/coding/pinot/pinot/generative/semi_supervised_net.py", line 155, in loss
    total_loss = self.loss_unsupervised(g, h) * self.unsup_scale
  File "/home/nguyenm5/coding/pinot/pinot/generative/semi_supervised_net.py", line 267, in loss_unsupervised
    recon_loss = self.decoder.decode_and_compute_recon_error(g, z_sample)
  File "/home/nguyenm5/coding/pinot/pinot/generative/decoder.py", line 295, in decode_and_compute_recon_error
    decoded_subgraphs = self.forward(g, z_sample)
  File "/home/nguyenm5/coding/pinot/pinot/generative/decoder.py", line 412, in forward
    decoded_subgraphs = [
  File "/home/nguyenm5/coding/pinot/pinot/generative/decoder.py", line 413, in <listcomp>
    self.decode(g_sample.ndata["h"]) for g_sample in gs_unbatched
  File "/home/nguyenm5/coding/pinot/pinot/generative/decoder.py", line 371, in decode
    temp1 = zx.repeat(1, n).view(n * n, h)  # Shape should be (n, n, Dx2)
RuntimeError: CUDA out of memory. Tried to allocate 2.00 MiB (GPU 0; 10.92 GiB total capacity; 10.12 GiB already allocated; 3.06 MiB free; 10.14 GiB reserved in total by PyTorch)
Using backend: pytorch
Traceback (most recent call last):
  File "scripts/active/belief_active_plot.py", line 649, in <module>
    best_df, pro_ts_df, retro_ts_df = plot.generate()
  File "scripts/active/belief_active_plot.py", line 257, in generate
    final_results, prospective_beliefs, retrospective_beliefs = self.run_trials(ds)
  File "scripts/active/belief_active_plot.py", line 327, in run_trials
    acquisitions = self.bo.run(num_rounds=self.num_rounds)
  File "/home/nguyenm5/coding/pinot/pinot/active/experiment.py", line 388, in run
    self.train()
  File "/home/nguyenm5/coding/pinot/pinot/active/experiment.py", line 464, in train
    self.net = pinot.app.experiment.Train(
  File "/home/nguyenm5/coding/pinot/pinot/app/experiment.py", line 117, in train
    epoch_loss = self.train_once()
  File "/home/nguyenm5/coding/pinot/pinot/app/experiment.py", line 92, in train_once
    loss = torch.sum(self.net.loss(*x))
  File "/home/nguyenm5/coding/pinot/pinot/generative/semi_supervised_net.py", line 155, in loss
    total_loss = self.loss_unsupervised(g, h) * self.unsup_scale
  File "/home/nguyenm5/coding/pinot/pinot/generative/semi_supervised_net.py", line 267, in loss_unsupervised
    recon_loss = self.decoder.decode_and_compute_recon_error(g, z_sample)
  File "/home/nguyenm5/coding/pinot/pinot/generative/decoder.py", line 295, in decode_and_compute_recon_error
    decoded_subgraphs = self.forward(g, z_sample)
  File "/home/nguyenm5/coding/pinot/pinot/generative/decoder.py", line 412, in forward
    decoded_subgraphs = [
  File "/home/nguyenm5/coding/pinot/pinot/generative/decoder.py", line 413, in <listcomp>
    self.decode(g_sample.ndata["h"]) for g_sample in gs_unbatched
  File "/home/nguyenm5/coding/pinot/pinot/generative/decoder.py", line 382, in decode
    E_tilde = self.e_tensor_to_E_tilde(e_tensor.view(n * n, 2 * h))
  File "/home/nguyenm5/anaconda3/envs/pinot/lib/python3.8/site-packages/torch/nn/modules/module.py", line 550, in __call__
    result = self.forward(*input, **kwargs)
  File "/home/nguyenm5/anaconda3/envs/pinot/lib/python3.8/site-packages/torch/nn/modules/container.py", line 100, in forward
    input = module(input)
  File "/home/nguyenm5/anaconda3/envs/pinot/lib/python3.8/site-packages/torch/nn/modules/module.py", line 550, in __call__
    result = self.forward(*input, **kwargs)
  File "/home/nguyenm5/anaconda3/envs/pinot/lib/python3.8/site-packages/torch/nn/modules/linear.py", line 87, in forward
    return F.linear(input, self.weight, self.bias)
  File "/home/nguyenm5/anaconda3/envs/pinot/lib/python3.8/site-packages/torch/nn/functional.py", line 1610, in linear
    ret = torch.addmm(bias, input, weight.t())
RuntimeError: CUDA out of memory. Tried to allocate 2.00 MiB (GPU 0; 7.80 GiB total capacity; 6.76 GiB already allocated; 3.12 MiB free; 6.78 GiB reserved in total by PyTorch)
Using backend: pytorch
Traceback (most recent call last):
  File "scripts/active/belief_active_plot.py", line 649, in <module>
    best_df, pro_ts_df, retro_ts_df = plot.generate()
  File "scripts/active/belief_active_plot.py", line 257, in generate
    final_results, prospective_beliefs, retrospective_beliefs = self.run_trials(ds)
  File "scripts/active/belief_active_plot.py", line 327, in run_trials
    acquisitions = self.bo.run(num_rounds=self.num_rounds)
  File "/home/nguyenm5/coding/pinot/pinot/active/experiment.py", line 388, in run
    self.train()
  File "/home/nguyenm5/coding/pinot/pinot/active/experiment.py", line 464, in train
    self.net = pinot.app.experiment.Train(
  File "/home/nguyenm5/coding/pinot/pinot/app/experiment.py", line 117, in train
    epoch_loss = self.train_once()
  File "/home/nguyenm5/coding/pinot/pinot/app/experiment.py", line 92, in train_once
    loss = torch.sum(self.net.loss(*x))
  File "/home/nguyenm5/coding/pinot/pinot/generative/semi_supervised_net.py", line 155, in loss
    total_loss = self.loss_unsupervised(g, h) * self.unsup_scale
  File "/home/nguyenm5/coding/pinot/pinot/generative/semi_supervised_net.py", line 267, in loss_unsupervised
    recon_loss = self.decoder.decode_and_compute_recon_error(g, z_sample)
  File "/home/nguyenm5/coding/pinot/pinot/generative/decoder.py", line 295, in decode_and_compute_recon_error
    decoded_subgraphs = self.forward(g, z_sample)
  File "/home/nguyenm5/coding/pinot/pinot/generative/decoder.py", line 412, in forward
    decoded_subgraphs = [
  File "/home/nguyenm5/coding/pinot/pinot/generative/decoder.py", line 413, in <listcomp>
    self.decode(g_sample.ndata["h"]) for g_sample in gs_unbatched
  File "/home/nguyenm5/coding/pinot/pinot/generative/decoder.py", line 373, in decode
    temp = torch.cat(
RuntimeError: CUDA out of memory. Tried to allocate 2.00 MiB (GPU 0; 7.93 GiB total capacity; 7.17 GiB already allocated; 4.12 MiB free; 7.19 GiB reserved in total by PyTorch)
Using backend: pytorch
Traceback (most recent call last):
  File "scripts/active/belief_active_plot.py", line 649, in <module>
    best_df, pro_ts_df, retro_ts_df = plot.generate()
  File "scripts/active/belief_active_plot.py", line 257, in generate
    final_results, prospective_beliefs, retrospective_beliefs = self.run_trials(ds)
  File "scripts/active/belief_active_plot.py", line 327, in run_trials
    acquisitions = self.bo.run(num_rounds=self.num_rounds)
  File "/home/nguyenm5/coding/pinot/pinot/active/experiment.py", line 388, in run
    self.train()
  File "/home/nguyenm5/coding/pinot/pinot/active/experiment.py", line 464, in train
    self.net = pinot.app.experiment.Train(
  File "/home/nguyenm5/coding/pinot/pinot/app/experiment.py", line 117, in train
    epoch_loss = self.train_once()
  File "/home/nguyenm5/coding/pinot/pinot/app/experiment.py", line 92, in train_once
    loss = torch.sum(self.net.loss(*x))
  File "/home/nguyenm5/coding/pinot/pinot/generative/semi_supervised_net.py", line 153, in loss
    h = self.representation.forward(g, pool=None)  # We always call this
  File "/home/nguyenm5/coding/pinot/pinot/representation/sequential.py", line 344, in forward
    h = getattr(self, exe)(g, h)
  File "/home/nguyenm5/anaconda3/envs/pinot/lib/python3.8/site-packages/torch/nn/modules/module.py", line 550, in __call__
    result = self.forward(*input, **kwargs)
  File "/home/nguyenm5/anaconda3/envs/pinot/lib/python3.8/site-packages/dgl/nn/pytorch/conv/graphconv.py", line 160, in forward
    rst = th.matmul(rst, weight)
RuntimeError: CUDA out of memory. Tried to allocate 350.00 MiB (GPU 0; 7.93 GiB total capacity; 6.57 GiB already allocated; 84.12 MiB free; 6.88 GiB reserved in total by PyTorch)
Using backend: pytorch
Traceback (most recent call last):
  File "scripts/active/belief_active_plot.py", line 649, in <module>
    best_df, pro_ts_df, retro_ts_df = plot.generate()
  File "scripts/active/belief_active_plot.py", line 257, in generate
    final_results, prospective_beliefs, retrospective_beliefs = self.run_trials(ds)
  File "scripts/active/belief_active_plot.py", line 327, in run_trials
    acquisitions = self.bo.run(num_rounds=self.num_rounds)
  File "/home/nguyenm5/coding/pinot/pinot/active/experiment.py", line 388, in run
    self.train()
  File "/home/nguyenm5/coding/pinot/pinot/active/experiment.py", line 464, in train
    self.net = pinot.app.experiment.Train(
  File "/home/nguyenm5/coding/pinot/pinot/app/experiment.py", line 117, in train
    epoch_loss = self.train_once()
  File "/home/nguyenm5/coding/pinot/pinot/app/experiment.py", line 92, in train_once
    loss = torch.sum(self.net.loss(*x))
  File "/home/nguyenm5/coding/pinot/pinot/generative/semi_supervised_net.py", line 155, in loss
    total_loss = self.loss_unsupervised(g, h) * self.unsup_scale
  File "/home/nguyenm5/coding/pinot/pinot/generative/semi_supervised_net.py", line 267, in loss_unsupervised
    recon_loss = self.decoder.decode_and_compute_recon_error(g, z_sample)
  File "/home/nguyenm5/coding/pinot/pinot/generative/decoder.py", line 295, in decode_and_compute_recon_error
    decoded_subgraphs = self.forward(g, z_sample)
  File "/home/nguyenm5/coding/pinot/pinot/generative/decoder.py", line 412, in forward
    decoded_subgraphs = [
  File "/home/nguyenm5/coding/pinot/pinot/generative/decoder.py", line 413, in <listcomp>
    self.decode(g_sample.ndata["h"]) for g_sample in gs_unbatched
  File "/home/nguyenm5/coding/pinot/pinot/generative/decoder.py", line 382, in decode
    E_tilde = self.e_tensor_to_E_tilde(e_tensor.view(n * n, 2 * h))
  File "/home/nguyenm5/anaconda3/envs/pinot/lib/python3.8/site-packages/torch/nn/modules/module.py", line 550, in __call__
    result = self.forward(*input, **kwargs)
  File "/home/nguyenm5/anaconda3/envs/pinot/lib/python3.8/site-packages/torch/nn/modules/container.py", line 100, in forward
    input = module(input)
  File "/home/nguyenm5/anaconda3/envs/pinot/lib/python3.8/site-packages/torch/nn/modules/module.py", line 550, in __call__
    result = self.forward(*input, **kwargs)
  File "/home/nguyenm5/anaconda3/envs/pinot/lib/python3.8/site-packages/torch/nn/modules/activation.py", line 94, in forward
    return F.relu(input, inplace=self.inplace)
  File "/home/nguyenm5/anaconda3/envs/pinot/lib/python3.8/site-packages/torch/nn/functional.py", line 1063, in relu
    result = torch.relu(input)
RuntimeError: CUDA out of memory. Tried to allocate 2.00 MiB (GPU 0; 7.80 GiB total capacity; 6.76 GiB already allocated; 3.12 MiB free; 6.78 GiB reserved in total by PyTorch)
Using backend: pytorch
Traceback (most recent call last):
  File "scripts/active/belief_active_plot.py", line 649, in <module>
    best_df, pro_ts_df, retro_ts_df = plot.generate()
  File "scripts/active/belief_active_plot.py", line 257, in generate
    final_results, prospective_beliefs, retrospective_beliefs = self.run_trials(ds)
  File "scripts/active/belief_active_plot.py", line 327, in run_trials
    acquisitions = self.bo.run(num_rounds=self.num_rounds)
  File "/home/nguyenm5/coding/pinot/pinot/active/experiment.py", line 388, in run
    self.train()
  File "/home/nguyenm5/coding/pinot/pinot/active/experiment.py", line 464, in train
    self.net = pinot.app.experiment.Train(
  File "/home/nguyenm5/coding/pinot/pinot/app/experiment.py", line 117, in train
    epoch_loss = self.train_once()
  File "/home/nguyenm5/coding/pinot/pinot/app/experiment.py", line 92, in train_once
    loss = torch.sum(self.net.loss(*x))
  File "/home/nguyenm5/coding/pinot/pinot/generative/semi_supervised_net.py", line 155, in loss
    total_loss = self.loss_unsupervised(g, h) * self.unsup_scale
  File "/home/nguyenm5/coding/pinot/pinot/generative/semi_supervised_net.py", line 264, in loss_unsupervised
    z_sample = distribution.rsample()
  File "/home/nguyenm5/anaconda3/envs/pinot/lib/python3.8/site-packages/torch/distributions/normal.py", line 68, in rsample
    return self.loc + eps * self.scale
RuntimeError: CUDA out of memory. Tried to allocate 350.00 MiB (GPU 0; 10.92 GiB total capacity; 9.30 GiB already allocated; 303.06 MiB free; 9.61 GiB reserved in total by PyTorch)
Using backend: pytorch
Traceback (most recent call last):
  File "scripts/active/belief_active_plot.py", line 649, in <module>
    best_df, pro_ts_df, retro_ts_df = plot.generate()
  File "scripts/active/belief_active_plot.py", line 257, in generate
    final_results, prospective_beliefs, retrospective_beliefs = self.run_trials(ds)
  File "scripts/active/belief_active_plot.py", line 327, in run_trials
    acquisitions = self.bo.run(num_rounds=self.num_rounds)
  File "/home/nguyenm5/coding/pinot/pinot/active/experiment.py", line 388, in run
    self.train()
  File "/home/nguyenm5/coding/pinot/pinot/active/experiment.py", line 464, in train
    self.net = pinot.app.experiment.Train(
  File "/home/nguyenm5/coding/pinot/pinot/app/experiment.py", line 117, in train
    epoch_loss = self.train_once()
  File "/home/nguyenm5/coding/pinot/pinot/app/experiment.py", line 92, in train_once
    loss = torch.sum(self.net.loss(*x))
  File "/home/nguyenm5/coding/pinot/pinot/generative/semi_supervised_net.py", line 155, in loss
    total_loss = self.loss_unsupervised(g, h) * self.unsup_scale
  File "/home/nguyenm5/coding/pinot/pinot/generative/semi_supervised_net.py", line 264, in loss_unsupervised
    z_sample = distribution.rsample()
  File "/home/nguyenm5/anaconda3/envs/pinot/lib/python3.8/site-packages/torch/distributions/normal.py", line 68, in rsample
    return self.loc + eps * self.scale
RuntimeError: CUDA out of memory. Tried to allocate 350.00 MiB (GPU 0; 10.92 GiB total capacity; 9.30 GiB already allocated; 303.06 MiB free; 9.61 GiB reserved in total by PyTorch)
Using backend: pytorch
Traceback (most recent call last):
  File "scripts/active/belief_active_plot.py", line 649, in <module>
    best_df, pro_ts_df, retro_ts_df = plot.generate()
  File "scripts/active/belief_active_plot.py", line 257, in generate
    final_results, prospective_beliefs, retrospective_beliefs = self.run_trials(ds)
  File "scripts/active/belief_active_plot.py", line 327, in run_trials
    acquisitions = self.bo.run(num_rounds=self.num_rounds)
  File "/home/nguyenm5/coding/pinot/pinot/active/experiment.py", line 388, in run
    self.train()
  File "/home/nguyenm5/coding/pinot/pinot/active/experiment.py", line 464, in train
    self.net = pinot.app.experiment.Train(
  File "/home/nguyenm5/coding/pinot/pinot/app/experiment.py", line 117, in train
    epoch_loss = self.train_once()
  File "/home/nguyenm5/coding/pinot/pinot/app/experiment.py", line 92, in train_once
    loss = torch.sum(self.net.loss(*x))
  File "/home/nguyenm5/coding/pinot/pinot/generative/semi_supervised_net.py", line 155, in loss
    total_loss = self.loss_unsupervised(g, h) * self.unsup_scale
  File "/home/nguyenm5/coding/pinot/pinot/generative/semi_supervised_net.py", line 267, in loss_unsupervised
    recon_loss = self.decoder.decode_and_compute_recon_error(g, z_sample)
  File "/home/nguyenm5/coding/pinot/pinot/generative/decoder.py", line 295, in decode_and_compute_recon_error
    decoded_subgraphs = self.forward(g, z_sample)
  File "/home/nguyenm5/coding/pinot/pinot/generative/decoder.py", line 412, in forward
    decoded_subgraphs = [
  File "/home/nguyenm5/coding/pinot/pinot/generative/decoder.py", line 413, in <listcomp>
    self.decode(g_sample.ndata["h"]) for g_sample in gs_unbatched
  File "/home/nguyenm5/coding/pinot/pinot/generative/decoder.py", line 373, in decode
    temp = torch.cat(
RuntimeError: CUDA out of memory. Tried to allocate 2.00 MiB (GPU 0; 7.80 GiB total capacity; 6.76 GiB already allocated; 3.12 MiB free; 6.78 GiB reserved in total by PyTorch)
Using backend: pytorch
Traceback (most recent call last):
  File "scripts/active/belief_active_plot.py", line 649, in <module>
    best_df, pro_ts_df, retro_ts_df = plot.generate()
  File "scripts/active/belief_active_plot.py", line 257, in generate
    final_results, prospective_beliefs, retrospective_beliefs = self.run_trials(ds)
  File "scripts/active/belief_active_plot.py", line 327, in run_trials
    acquisitions = self.bo.run(num_rounds=self.num_rounds)
  File "/home/nguyenm5/coding/pinot/pinot/active/experiment.py", line 388, in run
    self.train()
  File "/home/nguyenm5/coding/pinot/pinot/active/experiment.py", line 464, in train
    self.net = pinot.app.experiment.Train(
  File "/home/nguyenm5/coding/pinot/pinot/app/experiment.py", line 117, in train
    epoch_loss = self.train_once()
  File "/home/nguyenm5/coding/pinot/pinot/app/experiment.py", line 92, in train_once
    loss = torch.sum(self.net.loss(*x))
  File "/home/nguyenm5/coding/pinot/pinot/generative/semi_supervised_net.py", line 155, in loss
    total_loss = self.loss_unsupervised(g, h) * self.unsup_scale
  File "/home/nguyenm5/coding/pinot/pinot/generative/semi_supervised_net.py", line 267, in loss_unsupervised
    recon_loss = self.decoder.decode_and_compute_recon_error(g, z_sample)
  File "/home/nguyenm5/coding/pinot/pinot/generative/decoder.py", line 295, in decode_and_compute_recon_error
    decoded_subgraphs = self.forward(g, z_sample)
  File "/home/nguyenm5/coding/pinot/pinot/generative/decoder.py", line 412, in forward
    decoded_subgraphs = [
  File "/home/nguyenm5/coding/pinot/pinot/generative/decoder.py", line 413, in <listcomp>
    self.decode(g_sample.ndata["h"]) for g_sample in gs_unbatched
  File "/home/nguyenm5/coding/pinot/pinot/generative/decoder.py", line 382, in decode
    E_tilde = self.e_tensor_to_E_tilde(e_tensor.view(n * n, 2 * h))
  File "/home/nguyenm5/anaconda3/envs/pinot/lib/python3.8/site-packages/torch/nn/modules/module.py", line 550, in __call__
    result = self.forward(*input, **kwargs)
  File "/home/nguyenm5/anaconda3/envs/pinot/lib/python3.8/site-packages/torch/nn/modules/container.py", line 100, in forward
    input = module(input)
  File "/home/nguyenm5/anaconda3/envs/pinot/lib/python3.8/site-packages/torch/nn/modules/module.py", line 550, in __call__
    result = self.forward(*input, **kwargs)
  File "/home/nguyenm5/anaconda3/envs/pinot/lib/python3.8/site-packages/torch/nn/modules/linear.py", line 87, in forward
    return F.linear(input, self.weight, self.bias)
  File "/home/nguyenm5/anaconda3/envs/pinot/lib/python3.8/site-packages/torch/nn/functional.py", line 1610, in linear
    ret = torch.addmm(bias, input, weight.t())
RuntimeError: CUDA out of memory. Tried to allocate 2.00 MiB (GPU 0; 10.92 GiB total capacity; 10.12 GiB already allocated; 3.06 MiB free; 10.14 GiB reserved in total by PyTorch)
Using backend: pytorch
Traceback (most recent call last):
  File "scripts/active/belief_active_plot.py", line 649, in <module>
    best_df, pro_ts_df, retro_ts_df = plot.generate()
  File "scripts/active/belief_active_plot.py", line 257, in generate
    final_results, prospective_beliefs, retrospective_beliefs = self.run_trials(ds)
  File "scripts/active/belief_active_plot.py", line 327, in run_trials
    acquisitions = self.bo.run(num_rounds=self.num_rounds)
  File "/home/nguyenm5/coding/pinot/pinot/active/experiment.py", line 388, in run
    self.train()
  File "/home/nguyenm5/coding/pinot/pinot/active/experiment.py", line 464, in train
    self.net = pinot.app.experiment.Train(
  File "/home/nguyenm5/coding/pinot/pinot/app/experiment.py", line 117, in train
    epoch_loss = self.train_once()
  File "/home/nguyenm5/coding/pinot/pinot/app/experiment.py", line 92, in train_once
    loss = torch.sum(self.net.loss(*x))
  File "/home/nguyenm5/coding/pinot/pinot/generative/semi_supervised_net.py", line 155, in loss
    total_loss = self.loss_unsupervised(g, h) * self.unsup_scale
  File "/home/nguyenm5/coding/pinot/pinot/generative/semi_supervised_net.py", line 264, in loss_unsupervised
    z_sample = distribution.rsample()
  File "/home/nguyenm5/anaconda3/envs/pinot/lib/python3.8/site-packages/torch/distributions/normal.py", line 68, in rsample
    return self.loc + eps * self.scale
RuntimeError: CUDA out of memory. Tried to allocate 350.00 MiB (GPU 0; 10.92 GiB total capacity; 9.30 GiB already allocated; 303.06 MiB free; 9.61 GiB reserved in total by PyTorch)
Using backend: pytorch
Traceback (most recent call last):
  File "scripts/active/belief_active_plot.py", line 649, in <module>
    best_df, pro_ts_df, retro_ts_df = plot.generate()
  File "scripts/active/belief_active_plot.py", line 257, in generate
    final_results, prospective_beliefs, retrospective_beliefs = self.run_trials(ds)
  File "scripts/active/belief_active_plot.py", line 327, in run_trials
    acquisitions = self.bo.run(num_rounds=self.num_rounds)
  File "/home/nguyenm5/coding/pinot/pinot/active/experiment.py", line 388, in run
    self.train()
  File "/home/nguyenm5/coding/pinot/pinot/active/experiment.py", line 464, in train
    self.net = pinot.app.experiment.Train(
  File "/home/nguyenm5/coding/pinot/pinot/app/experiment.py", line 117, in train
    epoch_loss = self.train_once()
  File "/home/nguyenm5/coding/pinot/pinot/app/experiment.py", line 92, in train_once
    loss = torch.sum(self.net.loss(*x))
  File "/home/nguyenm5/coding/pinot/pinot/generative/semi_supervised_net.py", line 153, in loss
    h = self.representation.forward(g, pool=None)  # We always call this
  File "/home/nguyenm5/coding/pinot/pinot/representation/sequential.py", line 344, in forward
    h = getattr(self, exe)(g, h)
  File "/home/nguyenm5/anaconda3/envs/pinot/lib/python3.8/site-packages/torch/nn/modules/module.py", line 550, in __call__
    result = self.forward(*input, **kwargs)
  File "/home/nguyenm5/anaconda3/envs/pinot/lib/python3.8/site-packages/dgl/nn/pytorch/conv/graphconv.py", line 156, in forward
    graph.update_all(fn.copy_src(src='h', out='m'),
  File "/home/nguyenm5/anaconda3/envs/pinot/lib/python3.8/site-packages/dgl/graph.py", line 3238, in update_all
    Runtime.run(prog)
  File "/home/nguyenm5/anaconda3/envs/pinot/lib/python3.8/site-packages/dgl/runtime/runtime.py", line 11, in run
    exe.run()
  File "/home/nguyenm5/anaconda3/envs/pinot/lib/python3.8/site-packages/dgl/runtime/ir/executor.py", line 1198, in run
    self.ret.data = F.copy_reduce(
  File "/home/nguyenm5/anaconda3/envs/pinot/lib/python3.8/site-packages/dgl/backend/pytorch/tensor.py", line 432, in copy_reduce
    out_data = in_data.new_empty((out_size,) + in_data.shape[1:])
RuntimeError: CUDA out of memory. Tried to allocate 350.00 MiB (GPU 0; 7.80 GiB total capacity; 6.23 GiB already allocated; 11.12 MiB free; 6.54 GiB reserved in total by PyTorch)
Using backend: pytorch
Traceback (most recent call last):
  File "scripts/active/belief_active_plot.py", line 649, in <module>
    best_df, pro_ts_df, retro_ts_df = plot.generate()
  File "scripts/active/belief_active_plot.py", line 257, in generate
    final_results, prospective_beliefs, retrospective_beliefs = self.run_trials(ds)
  File "scripts/active/belief_active_plot.py", line 327, in run_trials
    acquisitions = self.bo.run(num_rounds=self.num_rounds)
  File "/home/nguyenm5/coding/pinot/pinot/active/experiment.py", line 388, in run
    self.train()
  File "/home/nguyenm5/coding/pinot/pinot/active/experiment.py", line 464, in train
    self.net = pinot.app.experiment.Train(
  File "/home/nguyenm5/coding/pinot/pinot/app/experiment.py", line 117, in train
    epoch_loss = self.train_once()
  File "/home/nguyenm5/coding/pinot/pinot/app/experiment.py", line 92, in train_once
    loss = torch.sum(self.net.loss(*x))
  File "/home/nguyenm5/coding/pinot/pinot/generative/semi_supervised_net.py", line 155, in loss
    total_loss = self.loss_unsupervised(g, h) * self.unsup_scale
  File "/home/nguyenm5/coding/pinot/pinot/generative/semi_supervised_net.py", line 267, in loss_unsupervised
    recon_loss = self.decoder.decode_and_compute_recon_error(g, z_sample)
  File "/home/nguyenm5/coding/pinot/pinot/generative/decoder.py", line 295, in decode_and_compute_recon_error
    decoded_subgraphs = self.forward(g, z_sample)
  File "/home/nguyenm5/coding/pinot/pinot/generative/decoder.py", line 412, in forward
    decoded_subgraphs = [
  File "/home/nguyenm5/coding/pinot/pinot/generative/decoder.py", line 413, in <listcomp>
    self.decode(g_sample.ndata["h"]) for g_sample in gs_unbatched
  File "/home/nguyenm5/coding/pinot/pinot/generative/decoder.py", line 373, in decode
    temp = torch.cat(
RuntimeError: CUDA out of memory. Tried to allocate 2.00 MiB (GPU 0; 10.92 GiB total capacity; 10.12 GiB already allocated; 3.06 MiB free; 10.14 GiB reserved in total by PyTorch)
Using backend: pytorch
Traceback (most recent call last):
  File "scripts/active/belief_active_plot.py", line 14, in <module>
    import pinot
  File "/home/nguyenm5/coding/pinot/pinot/__init__.py", line 2, in <module>
    import pinot.graph
  File "/home/nguyenm5/coding/pinot/pinot/graph.py", line 7, in <module>
    import dgl
  File "/home/nguyenm5/anaconda3/envs/pinot/lib/python3.8/site-packages/dgl/__init__.py", line 11, in <module>
    from . import contrib
  File "/home/nguyenm5/anaconda3/envs/pinot/lib/python3.8/site-packages/dgl/contrib/__init__.py", line 1, in <module>
    from . import sampling
  File "/home/nguyenm5/anaconda3/envs/pinot/lib/python3.8/site-packages/dgl/contrib/sampling/__init__.py", line 1, in <module>
    from .sampler import NeighborSampler, LayerSampler, EdgeSampler
  File "/home/nguyenm5/anaconda3/envs/pinot/lib/python3.8/site-packages/dgl/contrib/sampling/sampler.py", line 13, in <module>
    from ...nodeflow import NodeFlow
  File "/home/nguyenm5/anaconda3/envs/pinot/lib/python3.8/site-packages/dgl/nodeflow.py", line 9, in <module>
    from .graph import DGLBaseGraph
  File "/home/nguyenm5/anaconda3/envs/pinot/lib/python3.8/site-packages/dgl/graph.py", line 8, in <module>
    import networkx as nx
  File "/home/nguyenm5/anaconda3/envs/pinot/lib/python3.8/site-packages/networkx/__init__.py", line 112, in <module>
    import networkx.generators
  File "/home/nguyenm5/anaconda3/envs/pinot/lib/python3.8/site-packages/networkx/generators/__init__.py", line 16, in <module>
    from networkx.generators.intersection import *
  File "/home/nguyenm5/anaconda3/envs/pinot/lib/python3.8/site-packages/networkx/generators/intersection.py", line 13, in <module>
    from networkx.algorithms import bipartite
  File "/home/nguyenm5/anaconda3/envs/pinot/lib/python3.8/site-packages/networkx/algorithms/__init__.py", line 27, in <module>
    from networkx.algorithms.link_analysis import *
  File "/home/nguyenm5/anaconda3/envs/pinot/lib/python3.8/site-packages/networkx/algorithms/link_analysis/__init__.py", line 2, in <module>
    from networkx.algorithms.link_analysis.hits_alg import *
  File "<frozen importlib._bootstrap>", line 991, in _find_and_load
  File "<frozen importlib._bootstrap>", line 975, in _find_and_load_unlocked
  File "<frozen importlib._bootstrap>", line 671, in _load_unlocked
  File "<frozen importlib._bootstrap_external>", line 779, in exec_module
  File "<frozen importlib._bootstrap_external>", line 874, in get_code
  File "<frozen importlib._bootstrap_external>", line 973, in get_data
KeyboardInterrupt
Using backend: pytorch
Traceback (most recent call last):
  File "scripts/active/belief_active_plot.py", line 14, in <module>
    import pinot
  File "/home/nguyenm5/coding/pinot/pinot/__init__.py", line 2, in <module>
    import pinot.graph
  File "/home/nguyenm5/coding/pinot/pinot/graph.py", line 7, in <module>
    import dgl
  File "/home/nguyenm5/anaconda3/envs/pinot/lib/python3.8/site-packages/dgl/__init__.py", line 11, in <module>
    from . import contrib
  File "/home/nguyenm5/anaconda3/envs/pinot/lib/python3.8/site-packages/dgl/contrib/__init__.py", line 1, in <module>
    from . import sampling
  File "/home/nguyenm5/anaconda3/envs/pinot/lib/python3.8/site-packages/dgl/contrib/sampling/__init__.py", line 1, in <module>
    from .sampler import NeighborSampler, LayerSampler, EdgeSampler
  File "/home/nguyenm5/anaconda3/envs/pinot/lib/python3.8/site-packages/dgl/contrib/sampling/sampler.py", line 13, in <module>
    from ...nodeflow import NodeFlow
  File "/home/nguyenm5/anaconda3/envs/pinot/lib/python3.8/site-packages/dgl/nodeflow.py", line 9, in <module>
    from .graph import DGLBaseGraph
  File "/home/nguyenm5/anaconda3/envs/pinot/lib/python3.8/site-packages/dgl/graph.py", line 8, in <module>
    import networkx as nx
  File "/home/nguyenm5/anaconda3/envs/pinot/lib/python3.8/site-packages/networkx/__init__.py", line 112, in <module>
    import networkx.generators
  File "/home/nguyenm5/anaconda3/envs/pinot/lib/python3.8/site-packages/networkx/generators/__init__.py", line 16, in <module>
    from networkx.generators.intersection import *
  File "/home/nguyenm5/anaconda3/envs/pinot/lib/python3.8/site-packages/networkx/generators/intersection.py", line 13, in <module>
    from networkx.algorithms import bipartite
  File "/home/nguyenm5/anaconda3/envs/pinot/lib/python3.8/site-packages/networkx/algorithms/__init__.py", line 12, in <module>
    from networkx.algorithms.coloring import *
  File "/home/nguyenm5/anaconda3/envs/pinot/lib/python3.8/site-packages/networkx/algorithms/coloring/__init__.py", line 1, in <module>
    from networkx.algorithms.coloring.greedy_coloring import *
  File "/home/nguyenm5/anaconda3/envs/pinot/lib/python3.8/site-packages/networkx/algorithms/coloring/greedy_coloring.py", line 18, in <module>
    from . import greedy_coloring_with_interchange as _interchange
  File "<frozen importlib._bootstrap>", line 991, in _find_and_load
  File "<frozen importlib._bootstrap>", line 975, in _find_and_load_unlocked
  File "<frozen importlib._bootstrap>", line 671, in _load_unlocked
  File "<frozen importlib._bootstrap_external>", line 779, in exec_module
  File "<frozen importlib._bootstrap_external>", line 874, in get_code
  File "<frozen importlib._bootstrap_external>", line 973, in get_data
KeyboardInterrupt
Using backend: pytorch
Using backend: pytorch
Using backend: pytorch
Using backend: pytorch
Using backend: pytorch
Using backend: pytorch
Using backend: pytorch
Using backend: pytorch
Using backend: pytorch
Using backend: pytorch
